<?xml version="1.0"?>
<!-- dyn_pendulum2 — clean analytic 2R planar double pendulum (both axes about Y,
     masses offset along Z in the gravity plane). Phase 4 dynamics fixture. -->
<robot name="dyn_pendulum2">
  <link name="base"/>
  <link name="l1">
    <inertial><origin xyz="0 0 0.15" rpy="0 0 0"/><mass value="1.0"/>
      <inertia ixx="0.0085" ixy="0" ixz="0" iyy="0.0085" iyz="0" izz="0.0005"/></inertial>
  </link>
  <link name="l2">
    <inertial><origin xyz="0 0 0.15" rpy="0 0 0"/><mass value="1.0"/>
      <inertia ixx="0.0085" ixy="0" ixz="0" iyy="0.0085" iyz="0" izz="0.0005"/></inertial>
  </link>
  <joint name="j1" type="revolute">
    <parent link="base"/><child link="l1"/>
    <origin xyz="0 0 0" rpy="0 0 0"/><axis xyz="0 1 0"/>
    <limit lower="-3.14" upper="3.14" effort="20" velocity="10"/>
  </joint>
  <joint name="j2" type="revolute">
    <parent link="l1"/><child link="l2"/>
    <origin xyz="0 0 0.3" rpy="0 0 0"/><axis xyz="0 1 0"/>
    <limit lower="-3.14" upper="3.14" effort="20" velocity="10"/>
  </joint>
</robot>
