<?xml version="1.0"?>
<robot name="r7">
  <link name="L0"/>
  <link name="L1"/>
  <link name="L2"/>
  <link name="L3"/>
  <link name="L4"/>
  <link name="L5"/>
  <link name="L6"/>
  <link name="L7"/>
  <joint name="j1" type="revolute">
    <parent link="L0"/><child link="L1"/>
    <origin xyz="0 0 0.1" rpy="0 0 0"/><axis xyz="0 0 1"/>
    <limit lower="-2.9" upper="2.9" effort="1" velocity="1"/>
  </joint>
  <joint name="j2" type="revolute">
    <parent link="L1"/><child link="L2"/>
    <origin xyz="0 0 0.1" rpy="0 0 0"/><axis xyz="0 1 0"/>
    <limit lower="-2.9" upper="2.9" effort="1" velocity="1"/>
  </joint>
  <joint name="j3" type="revolute">
    <parent link="L2"/><child link="L3"/>
    <origin xyz="0.15 0 0" rpy="0 0 0"/><axis xyz="0 0 1"/>
    <limit lower="-2.9" upper="2.9" effort="1" velocity="1"/>
  </joint>
  <joint name="j4" type="revolute">
    <parent link="L3"/><child link="L4"/>
    <origin xyz="0.15 0 0" rpy="0 0 0"/><axis xyz="0 1 0"/>
    <limit lower="-2.9" upper="2.9" effort="1" velocity="1"/>
  </joint>
  <joint name="j5" type="revolute">
    <parent link="L4"/><child link="L5"/>
    <origin xyz="0.12 0 0" rpy="0 0 0"/><axis xyz="0 0 1"/>
    <limit lower="-2.9" upper="2.9" effort="1" velocity="1"/>
  </joint>
  <joint name="j6" type="revolute">
    <parent link="L5"/><child link="L6"/>
    <origin xyz="0.1 0 0" rpy="0 0 0"/><axis xyz="0 1 0"/>
    <limit lower="-2.9" upper="2.9" effort="1" velocity="1"/>
  </joint>
  <joint name="j7" type="revolute">
    <parent link="L6"/><child link="L7"/>
    <origin xyz="0.08 0 0" rpy="0 0 0"/><axis xyz="1 0 0"/>
    <limit lower="-2.9" upper="2.9" effort="1" velocity="1"/>
  </joint>
</robot>
