<?xml version="1.0"?>
<robot name="toy2">
  <link name="base"/>
  <link name="l1"/>
  <link name="l2"/>
  <joint name="j1" type="revolute">
    <parent link="base"/><child link="l1"/>
    <origin xyz="0 0 0.1" rpy="0 0 0"/><axis xyz="0 0 1"/>
    <limit lower="-3.14" upper="3.14" effort="10" velocity="3"/>
  </joint>
  <joint name="j2" type="revolute">
    <parent link="l1"/><child link="l2"/>
    <origin xyz="0.2 0 0" rpy="0 0 0"/><axis xyz="0 1 0"/>
    <limit lower="-3.14" upper="3.14" effort="10" velocity="3"/>
  </joint>
</robot>
